Traceback (most recent call last):
  File "/Users/silviags/opt/miniconda3/envs/PyQM/lib/python3.9/site-packages/jupyter_core/utils/__init__.py", line 154, in wrapped
    asyncio.get_running_loop()
RuntimeError: no running event loop

During handling of the above exception, another exception occurred:

Traceback (most recent call last):
  File "/Users/silviags/opt/miniconda3/envs/PyQM/lib/python3.9/site-packages/jupyter_cache/executors/utils.py", line 58, in single_nb_execution
    executenb(
  File "/Users/silviags/opt/miniconda3/envs/PyQM/lib/python3.9/site-packages/nbclient/client.py", line 1319, in execute
    return NotebookClient(nb=nb, resources=resources, km=km, **kwargs).execute()
  File "/Users/silviags/opt/miniconda3/envs/PyQM/lib/python3.9/site-packages/jupyter_core/utils/__init__.py", line 158, in wrapped
    return loop.run_until_complete(inner)
  File "/Users/silviags/opt/miniconda3/envs/PyQM/lib/python3.9/asyncio/base_events.py", line 647, in run_until_complete
    return future.result()
  File "/Users/silviags/opt/miniconda3/envs/PyQM/lib/python3.9/site-packages/nbclient/client.py", line 709, in async_execute
    await self.async_execute_cell(
  File "/Users/silviags/opt/miniconda3/envs/PyQM/lib/python3.9/site-packages/nbclient/client.py", line 1062, in async_execute_cell
    await self._check_raise_for_error(cell, cell_index, exec_reply)
  File "/Users/silviags/opt/miniconda3/envs/PyQM/lib/python3.9/site-packages/nbclient/client.py", line 918, in _check_raise_for_error
    raise CellExecutionError.from_cell_and_msg(cell, exec_reply_content)
nbclient.exceptions.CellExecutionError: An error occurred while executing the following cell:
------------------
def subtractor(a):
    b = 4
    return a-b

a=10
print(subtractor(a))
print(b)
------------------

----- stdout -----
6
------------------

[0;31m---------------------------------------------------------------------------[0m
[0;31mNameError[0m                                 Traceback (most recent call last)
[0;32m/var/folders/9b/hnjyg5ld18v94zj022rv_zzm0000gn/T/ipykernel_5453/3855322907.py[0m in [0;36m<cell line: 7>[0;34m()[0m
[1;32m      5[0m [0ma[0m[0;34m=[0m[0;36m10[0m[0;34m[0m[0;34m[0m[0m
[1;32m      6[0m [0mprint[0m[0;34m([0m[0msubtractor[0m[0;34m([0m[0ma[0m[0;34m)[0m[0;34m)[0m[0;34m[0m[0;34m[0m[0m
[0;32m----> 7[0;31m [0mprint[0m[0;34m([0m[0mb[0m[0;34m)[0m[0;34m[0m[0;34m[0m[0m
[0m
[0;31mNameError[0m: name 'b' is not defined

