Traceback (most recent call last):
  File "/Users/silviags/opt/miniconda3/envs/PyQM/lib/python3.9/site-packages/jupyter_core/utils/__init__.py", line 154, in wrapped
    asyncio.get_running_loop()
RuntimeError: no running event loop

During handling of the above exception, another exception occurred:

Traceback (most recent call last):
  File "/Users/silviags/opt/miniconda3/envs/PyQM/lib/python3.9/site-packages/jupyter_cache/executors/utils.py", line 58, in single_nb_execution
    executenb(
  File "/Users/silviags/opt/miniconda3/envs/PyQM/lib/python3.9/site-packages/nbclient/client.py", line 1319, in execute
    return NotebookClient(nb=nb, resources=resources, km=km, **kwargs).execute()
  File "/Users/silviags/opt/miniconda3/envs/PyQM/lib/python3.9/site-packages/jupyter_core/utils/__init__.py", line 158, in wrapped
    return loop.run_until_complete(inner)
  File "/Users/silviags/opt/miniconda3/envs/PyQM/lib/python3.9/asyncio/base_events.py", line 647, in run_until_complete
    return future.result()
  File "/Users/silviags/opt/miniconda3/envs/PyQM/lib/python3.9/site-packages/nbclient/client.py", line 709, in async_execute
    await self.async_execute_cell(
  File "/Users/silviags/opt/miniconda3/envs/PyQM/lib/python3.9/site-packages/nbclient/client.py", line 1062, in async_execute_cell
    await self._check_raise_for_error(cell, cell_index, exec_reply)
  File "/Users/silviags/opt/miniconda3/envs/PyQM/lib/python3.9/site-packages/nbclient/client.py", line 918, in _check_raise_for_error
    raise CellExecutionError.from_cell_and_msg(cell, exec_reply_content)
nbclient.exceptions.CellExecutionError: An error occurred while executing the following cell:
------------------
data1 = np.random.normal(0.0,1.0,500)
data2 = np.random.normal(0.0,1.0,5000)

bin_array = np.arange(-2.5,3,.5)

fig = plt.figure(figsize = (10,6))

ax1 = fig.add_axes([0,.5,.46,1])
ax1.hist(data1, density=True, bins=bin_array, color='r', orientation='horizontal')
ax1.set_xlabel('Data Set 1')

ax2 = fig.add_axes([.5,.5,.46,1])
ax2.hist(data2, density=True, bins=bin_array, color='b', orientation='horizontal')
ax2.set_xlabel('Data Set 2')

ax2.xaxis.tick_top()
ax1.xaxis.tick_top()
ax1.yaxis.tick_right()

ax2.get_shared_y_axes().join(ax1, ax2)
ax1.invert_xaxis()
ax2.set_yticklabels([])

plt.show()
------------------


[0;31m---------------------------------------------------------------------------[0m
[0;31mAttributeError[0m                            Traceback (most recent call last)
[0;32m/var/folders/9b/hnjyg5ld18v94zj022rv_zzm0000gn/T/ipykernel_4041/274506656.py[0m in [0;36m<cell line: 20>[0;34m()[0m
[1;32m     18[0m [0max1[0m[0;34m.[0m[0myaxis[0m[0;34m.[0m[0mtick_right[0m[0;34m([0m[0;34m)[0m[0;34m[0m[0;34m[0m[0m
[1;32m     19[0m [0;34m[0m[0m
[0;32m---> 20[0;31m [0max2[0m[0;34m.[0m[0mget_shared_y_axes[0m[0;34m([0m[0;34m)[0m[0;34m.[0m[0mjoin[0m[0;34m([0m[0max1[0m[0;34m,[0m [0max2[0m[0;34m)[0m[0;34m[0m[0;34m[0m[0m
[0m[1;32m     21[0m [0max1[0m[0;34m.[0m[0minvert_xaxis[0m[0;34m([0m[0;34m)[0m[0;34m[0m[0;34m[0m[0m
[1;32m     22[0m [0max2[0m[0;34m.[0m[0mset_yticklabels[0m[0;34m([0m[0;34m[[0m[0;34m][0m[0;34m)[0m[0;34m[0m[0;34m[0m[0m

[0;31mAttributeError[0m: 'GrouperView' object has no attribute 'join'

